<!--
Copyright 2022-2023 OmniSafe Team. All Rights Reserved.

 Licensed under the Apache License, Version 2.0 (the "License");
 you may not use this file except in compliance with the License.
 You may obtain a copy of the License at

     http://www.apache.org/licenses/LICENSE-2.0

 Unless required by applicable law or agreed to in writing, software
 distributed under the License is distributed on an "AS IS" BASIS,
 WITHOUT WARRANTIES OR CONDITIONS OF ANY KIND, either express or implied.
 See the License for the specific language governing permissions and
 limitations under the License.
-->

<mujoco model="ant">
  <size njmax="3000" nconmax="1000"/>
  <compiler angle="radian" coordinate="local" inertiafromgeom="true"/>
  <option integrator="RK4" timestep="0.01"/>
  <custom>
    <numeric data="0.0 0.0 0.55 1.0 0.0 0.0 0.0 0.0 1.0 0.0 -1.0 0.0 -1.0 0.0 1.0" name="init_qpos"/>
  </custom>
  <default>
    <joint armature="1" damping="1" limited="true"/>
    <geom condim="6" density="5.0"/>
    <site size="0.032" type="sphere"/>
  <default class="agent">
    <geom rgba="0.7412 0.0431 0.1843 1"/>
  </default>
  <default class="agent1">
    <geom rgba="0.0039 0.1529 0.3961 1"/>
  </default>
  </default>
  <worldbody>
    <geom name="floor" size="5 5 0.1" type="plane" condim="6" conaffinity="3"/>
    <body name="agent" pos="0 0 0.18" childclass="agent">
      <site name="agent" rgba="1 0 0 .1" pos="0 0 -0.02"/>
      <camera name="vision" pos="0 0.05 0.05" euler="1.57 0 0"/>
      <geom name="torso_geom" pos="0 0 0" size="0.0625" type="sphere"/>
      <joint armature="0" damping="0" limited="false" margin="0.01" name="root" pos="0 0 0" type="free"/>
      <body name="front_left_leg" pos="0 0 0">
        <geom fromto="0.0 0.0 0.0 0.05 0.05 0.0" name="aux_1_geom" size="0.02" type="capsule"/>
        <body name="aux_1" pos="0.05 0.05 0">
          <joint axis="0 0 1" name="hip_1" pos="0.0 0.0 0.0" range="-0.70 0.70" type="hinge"/>
          <geom fromto="0.0 0.0 0.0 0.05 0.05 0.0" name="left_leg_geom" size="0.02" type="capsule"/>
          <body pos="0.05 0.05 0" name="front_left_foot">
            <joint axis="-1 1 0" name="ankle_1" pos="0.0 0.0 0.0" range="0.52 1.74" type="hinge"/>
            <geom fromto="0.0 0.0 0.0 0.1 0.1 0.0" name="left_ankle_geom" size="0.02" type="capsule" density="50000.0"/>
          </body>
        </body>
      </body>
      <body name="front_right_leg" pos="0 0 0">
        <geom fromto="0.0 0.0 0.0 -0.05 0.05 0.0" name="aux_2_geom" size="0.02" type="capsule"/>
        <body name="aux_2" pos="-0.05 0.05 0">
          <joint axis="0 0 1" name="hip_2" pos="0.0 0.0 0.0" range="-0.70 0.70" type="hinge"/>
          <geom fromto="0.0 0.0 0.0 -0.05 0.05 0.0" name="right_leg_geom" size="0.02" type="capsule"/>
          <body pos="-0.05 0.05 0" name="front_right_foot">
            <joint axis="1 1 0" name="ankle_2" pos="0.0 0.0 0.0" range="-1.74 -0.52" type="hinge"/>
            <geom fromto="0.0 0.0 0.0 -0.1 0.1 0.0" name="right_ankle_geom" size="0.02" type="capsule" density="50000.0"/>
          </body>
        </body>
      </body>
      <body name="left_back_leg" pos="0 0 0">
        <geom fromto="0.0 0.0 0.0 -0.05 -0.05 0.0" name="aux_3_geom" size="0.02" type="capsule"/>
        <body name="aux_3" pos="-0.05 -0.05 0">
          <joint axis="0 0 1" name="hip_3" pos="0.0 0.0 0.0" range="-0.70 0.70" type="hinge"/>
          <geom fromto="0.0 0.0 0.0 -0.05 -0.05 0.0" name="back_leg_geom" size="0.02" type="capsule"/>
          <body pos="-0.05 -0.05 0" name="left_back_foot">
            <joint axis="-1 1 0" name="ankle_3" pos="0.0 0.0 0.0" range="-1.74 -0.52" type="hinge"/>
            <geom fromto="0.0 0.0 0.0 -0.1 -0.1 0.0" name="third_ankle_geom" size="0.02" type="capsule" density="50000.0"/>
          </body>
        </body>
      </body>
      <body name="right_back_leg" pos="0 0 0">
        <geom fromto="0.0 0.0 0.0 0.05 -0.05 0.0" name="aux_4_geom" size="0.02" type="capsule"/>
        <body name="aux_4" pos="0.05 -0.05 0">
          <joint axis="0 0 1" name="hip_4" pos="0.0 0.0 0.0" range="-0.70 0.70" type="hinge"/>
          <geom fromto="0.0 0.0 0.0 0.05 -0.05 0.0" name="rightback_leg_geom" size="0.02" type="capsule"/>
          <body pos="0.05 -0.05 0" name="right_back_foot">
            <joint axis="1 1 0" name="ankle_4" pos="0.0 0.0 0.0" range="0.52 1.74" type="hinge"/>
            <geom fromto="0.0 0.0 0.0 0.1 -0.1 0.0" name="fourth_ankle_geom" size="0.02" type="capsule" density="50000.0"/>
          </body>
        </body>
      </body>
    </body>
    <body name="agent1" pos="0 0 0.18" childclass="agent1">
      <site name="agent1" rgba="1 0 0 .1" pos="0 0 -0.02"/>
      <camera name="vision1" pos="0 0.05 0.05" euler="1.57 0 0"/>
      <geom name="torso_geom1" pos="0 0 0" size="0.0625" type="sphere"/>
      <joint armature="0" damping="0" limited="false" margin="0.01" name="root1" pos="0 0 0" type="free"/>
      <body name="front_left_leg1" pos="0 0 0">
        <geom fromto="0.0 0.0 0.0 0.05 0.05 0.0" name="aux_1_geom1" size="0.02" type="capsule"/>
        <body name="aux_11" pos="0.05 0.05 0">
          <joint axis="0 0 1" name="hip_11" pos="0.0 0.0 0.0" range="-0.70 0.70" type="hinge"/>
          <geom fromto="0.0 0.0 0.0 0.05 0.05 0.0" name="left_leg_geom1" size="0.02" type="capsule"/>
          <body pos="0.05 0.05 0" name="front_left_foot1">
            <joint axis="-1 1 0" name="ankle_11" pos="0.0 0.0 0.0" range="0.52 1.74" type="hinge"/>
            <geom fromto="0.0 0.0 0.0 0.1 0.1 0.0" name="left_ankle_geom1" size="0.02" type="capsule" density="50000.0"/>
          </body>
        </body>
      </body>
      <body name="front_right_leg1" pos="0 0 0">
        <geom fromto="0.0 0.0 0.0 -0.05 0.05 0.0" name="aux_2_geom1" size="0.02" type="capsule"/>
        <body name="aux_21" pos="-0.05 0.05 0">
          <joint axis="0 0 1" name="hip_21" pos="0.0 0.0 0.0" range="-0.70 0.70" type="hinge"/>
          <geom fromto="0.0 0.0 0.0 -0.05 0.05 0.0" name="right_leg_geom1" size="0.02" type="capsule"/>
          <body pos="-0.05 0.05 0" name="front_right_foot1">
            <joint axis="1 1 0" name="ankle_21" pos="0.0 0.0 0.0" range="-1.74 -0.52" type="hinge"/>
            <geom fromto="0.0 0.0 0.0 -0.1 0.1 0.0" name="right_ankle_geom1" size="0.02" type="capsule" density="50000.0"/>
          </body>
        </body>
      </body>
      <body name="left_back_leg1" pos="0 0 0">
        <geom fromto="0.0 0.0 0.0 -0.05 -0.05 0.0" name="aux_3_geom1" size="0.02" type="capsule"/>
        <body name="aux_31" pos="-0.05 -0.05 0">
          <joint axis="0 0 1" name="hip_31" pos="0.0 0.0 0.0" range="-0.70 0.70" type="hinge"/>
          <geom fromto="0.0 0.0 0.0 -0.05 -0.05 0.0" name="back_leg_geom1" size="0.02" type="capsule"/>
          <body pos="-0.05 -0.05 0" name="left_back_foot1">
            <joint axis="-1 1 0" name="ankle_31" pos="0.0 0.0 0.0" range="-1.74 -0.52" type="hinge"/>
            <geom fromto="0.0 0.0 0.0 -0.1 -0.1 0.0" name="third_ankle_geom1" size="0.02" type="capsule" density="50000.0"/>
          </body>
        </body>
      </body>
      <body name="right_back_leg1" pos="0 0 0">
        <geom fromto="0.0 0.0 0.0 0.05 -0.05 0.0" name="aux_4_geom1" size="0.02" type="capsule"/>
        <body name="aux_41" pos="0.05 -0.05 0">
          <joint axis="0 0 1" name="hip_41" pos="0.0 0.0 0.0" range="-0.70 0.70" type="hinge"/>
          <geom fromto="0.0 0.0 0.0 0.05 -0.05 0.0" name="rightback_leg_geom1" size="0.02" type="capsule"/>
          <body pos="0.05 -0.05 0" name="right_back_foot1">
            <joint axis="1 1 0" name="ankle_41" pos="0.0 0.0 0.0" range="0.52 1.74" type="hinge"/>
            <geom fromto="0.0 0.0 0.0 0.1 -0.1 0.0" name="fourth_ankle_geom1" size="0.02" type="capsule" density="50000.0"/>
          </body>
        </body>
      </body>
    </body>
  </worldbody>
  <sensor>
    <!-- Used for observation -->
    <accelerometer site="agent" name="accelerometer"/>
    <velocimeter site="agent" name="velocimeter"/>
    <gyro site="agent" name="gyro"/>
    <magnetometer site="agent" name="magnetometer"/>

    <!-- Used for intrinsic constraints -->
    <subtreecom body="agent" name="subtreecom"/>
    <subtreelinvel body="agent" name="subtreelinvel"/>
    <subtreeangmom body="agent" name="subtreeangmom"/>

    <framepos objtype="site" objname="agent" name="agent_pos"/>

    <jointpos joint="hip_1" name="hip_1"/>
    <jointpos joint="ankle_1" name="ankle_1"/>
    <jointpos joint="hip_2" name="hip_2"/>
    <jointpos joint="ankle_2" name="ankle_2"/>
    <jointpos joint="hip_3" name="hip_3"/>
    <jointpos joint="ankle_3" name="ankle_3"/>
    <jointpos joint="hip_4" name="hip_4"/>
    <jointpos joint="ankle_4" name="ankle_4"/>

    <frameangvel objtype="site" objname="agent" name="agent_qvel"/>

    <jointvel joint="hip_1" name="hip_1_vel"/>
    <jointvel joint="ankle_1" name="ankle_1_vel"/>
    <jointvel joint="hip_2" name="hip_2_vel"/>
    <jointvel joint="ankle_2" name="ankle_2_vel"/>
    <jointvel joint="hip_3" name="hip_3_vel"/>
    <jointvel joint="ankle_3" name="ankle_3_vel"/>
    <jointvel joint="hip_4" name="hip_4_vel"/>
    <jointvel joint="ankle_4" name="ankle_4_vel"/>

    <!-- Used for observation -->
    <accelerometer site="agent1" name="accelerometer1"/>
    <velocimeter site="agent1" name="velocimeter1"/>
    <gyro site="agent1" name="gyro1"/>
    <magnetometer site="agent1" name="magnetometer1"/>

    <!-- Used for intrinsic constraints -->
    <subtreecom body="agent1" name="subtreecom1"/>
    <subtreelinvel body="agent1" name="subtreelinvel1"/>
    <subtreeangmom body="agent1" name="subtreeangmom1"/>

    <framepos objtype="site" objname="agent1" name="agent_pos1"/>

    <jointpos joint="hip_11" name="hip_11"/>
    <jointpos joint="ankle_11" name="ankle_11"/>
    <jointpos joint="hip_21" name="hip_21"/>
    <jointpos joint="ankle_21" name="ankle_21"/>
    <jointpos joint="hip_31" name="hip_31"/>
    <jointpos joint="ankle_31" name="ankle_31"/>
    <jointpos joint="hip_41" name="hip_41"/>
    <jointpos joint="ankle_41" name="ankle_41"/>

    <frameangvel objtype="site" objname="agent1" name="agent_qvel1"/>

    <jointvel joint="hip_11" name="hip_1_vel1"/>
    <jointvel joint="ankle_11" name="ankle_1_vel1"/>
    <jointvel joint="hip_21" name="hip_2_vel1"/>
    <jointvel joint="ankle_21" name="ankle_2_vel1"/>
    <jointvel joint="hip_31" name="hip_3_vel1"/>
    <jointvel joint="ankle_31" name="ankle_3_vel1"/>
    <jointvel joint="hip_41" name="hip_4_vel1"/>
    <jointvel joint="ankle_41" name="ankle_4_vel1"/>
  </sensor>
  <actuator>
    <motor ctrllimited="true" ctrlrange="-1.0 1.0" joint="hip_1" gear="150"/>
    <motor ctrllimited="true" ctrlrange="-1.0 1.0" joint="ankle_1" gear="150"/>
    <motor ctrllimited="true" ctrlrange="-1.0 1.0" joint="hip_2" gear="150"/>
    <motor ctrllimited="true" ctrlrange="-1.0 1.0" joint="ankle_2" gear="150"/>
    <motor ctrllimited="true" ctrlrange="-1.0 1.0" joint="hip_3" gear="150"/>
    <motor ctrllimited="true" ctrlrange="-1.0 1.0" joint="ankle_3" gear="150"/>
    <motor ctrllimited="true" ctrlrange="-1.0 1.0" joint="hip_4" gear="150"/>
    <motor ctrllimited="true" ctrlrange="-1.0 1.0" joint="ankle_4" gear="150"/>

    <motor ctrllimited="true" ctrlrange="-1.0 1.0" joint="hip_11" gear="150"/>
    <motor ctrllimited="true" ctrlrange="-1.0 1.0" joint="ankle_11" gear="150"/>
    <motor ctrllimited="true" ctrlrange="-1.0 1.0" joint="hip_21" gear="150"/>
    <motor ctrllimited="true" ctrlrange="-1.0 1.0" joint="ankle_21" gear="150"/>
    <motor ctrllimited="true" ctrlrange="-1.0 1.0" joint="hip_31" gear="150"/>
    <motor ctrllimited="true" ctrlrange="-1.0 1.0" joint="ankle_31" gear="150"/>
    <motor ctrllimited="true" ctrlrange="-1.0 1.0" joint="hip_41" gear="150"/>
    <motor ctrllimited="true" ctrlrange="-1.0 1.0" joint="ankle_41" gear="150"/>
  </actuator>
</mujoco>
